<?xml version='1.0' encoding='utf-8'?>
<robot name="iam_bot">

    <material name="CHASIS_BLUE">
        <color rgba="0.153 0.165 0.412 1"/>
    </material>

    <material name="WHEEL_BLACK">
        <color rgba="0 0 0 1"/>
    </material>

    <material name="CASTER_SILVER">
        <color rgba="0.588 0.588 0.588 1"/>
    </material>

    <material name="LIDAR_GREY">
        <color rgba="0.392 0.392 0.392 1"/>
    </material>



    <link name="left_wheel">
        <inertial>
            <origin xyz="2.215487402943417e-06 -1.2770853251264923e-06 0.028132134803226502" rpy="0.0 -0.0 0.0" />
            <mass value="0.22391054430731744" />
            <inertia ixx="0.0002563571259650028" iyy="0.00025635048929468704" izz="0.0004042362139435962" ixy="1.3427957747461083e-13" iyz="7.380781082231419e-09" ixz="-1.2804091942524715e-08" />
        </inertial>
        <visual name="left_wheel_visual">
            <origin xyz="0.37160427410941455 0.031321737445734174 0.13277868183774832" rpy="3.0065623868209316e-15 9.473267377050172e-16 1.5707963267948957" />
            <geometry>
                <mesh filename="meshes/left_wheel.stl" scale="0.001 0.001 0.001" />
            </geometry>
            <material name="WHEEL_BLACK"/>
        </visual>
        <collision name="left_wheel_collision">
            <origin xyz="0.37160427410941455 0.031321737445734174 0.13277868183774832" rpy="3.0065623868209316e-15 9.473267377050172e-16 1.5707963267948957" />
            <geometry>
                <mesh filename="meshes/left_wheel.stl" scale="0.001 0.001 0.001" />
            </geometry>
        </collision>
    </link>

    <link name="base_link">
        <inertial>
            <origin xyz="-0.09398896984913316 -0.00033324205009904213 0.07713649206363926" rpy="0.0 0.0 0.0" />
            <mass value="2.072741935105781" />
            <inertia ixx="0.015324451649043452" iyy="0.029121616964427867" izz="0.03681388301778877" ixy="-4.936480620691103e-05" iyz="-1.4131264620040578e-05" ixz="0.00011474364571543993" />
        </inertial>
        <visual name="base_link_visual">
            <origin xyz="0.0 0.0 0.0" rpy="0.0 0.0 0.0" />
            <geometry>
                <mesh filename="meshes/base_link.stl" scale="0.001 0.001 0.001" />
            </geometry>
            <material name="CHASIS_BLUE"/>
        </visual>
        <collision name="base_link_collision">
            <origin xyz="0.0 0.0 0.0" rpy="0.0 0.0 0.0" />
            <geometry>
                <mesh filename="meshes/base_link_col.stl" scale="0.001 0.001 0.001" />
            </geometry>
        </collision>
    </link>

    <link name="top_lidar_sensor">
        <inertial>
            <origin xyz="0.02672210981515967 0.0002412625384381132 0.03237755864545555" rpy="0.0 -0.0 0.0" />
            <mass value="0.1901726292898517" />
            <inertia ixx="7.658129060059832e-05" iyy="0.00016331534109439126" izz="0.00018292909777217585" ixy="1.2253270879710822e-06" iyz="-6.807822780407632e-07" ixz="3.150541905402263e-05" />
        </inertial>
        <visual name="top_lidar_sensor_visual">
            <origin xyz="0.22158934999999993 0.00024120999999984366 -0.21008004999999996" rpy="4.930380657631321e-32 -0.0 0.0" />
            <geometry>
                <mesh filename="meshes/top_lidar_sensor.stl" scale="0.001 0.001 0.001" />
            </geometry>
            <material name="LIDAR_GREY"/>
        </visual>
        <collision name="top_lidar_sensor_collision">
            <origin xyz="0.22158934999999993 0.00024120999999984366 -0.21008004999999996" rpy="4.930380657631321e-32 -0.0 0.0" />
            <geometry>
                <mesh filename="meshes/top_lidar_sensor.stl" scale="0.001 0.001 0.001" />
            </geometry>
        </collision>
    </link>

    <link name="right_caster_connector">
        <inertial>
            <origin xyz="0.001405011953905806 2.106191058315332e-05 -0.0042219422652539865" rpy="0.0 -0.0 0.0" />
            <mass value="0.003960896655885569" />
            <inertia ixx="1.5703162104020672e-07" iyy="1.6777567965928458e-07" izz="1.7443859290356117e-07" ixy="-5.709200945051732e-10" iyz="8.589987253253116e-10" ixz="4.1927853383486225e-08" />
        </inertial>
        <visual name="right_caster_connector_visual">
            <origin xyz="0.20483935 -0.06500879000000001 -0.02858005" rpy="0.0 -0.0 0.0" />
            <geometry>
                <mesh filename="meshes/right_caster_connector.stl" scale="0.001 0.001 0.001" />
            </geometry>
            <material name="CASTER_SILVER"/>
        </visual>
        <collision name="right_caster_connector_collision">
            <origin xyz="0.20483935 -0.06500879000000001 -0.02858005" rpy="0.0 -0.0 0.0" />
            <geometry>
                <mesh filename="meshes/right_caster_connector.stl" scale="0.001 0.001 0.001" />
            </geometry>
        </collision>
    </link>

    <link name="right_caster_wheel">
        <inertial>
            <origin xyz="4.658980934379997e-09 1.4002450643424425e-09 0.003312139955989153" rpy="0.0 -0.0 0.0" />
            <mass value="0.014985308319104898" />
            <inertia ixx="4.3853143064445654e-07" iyy="4.3853142698072056e-07" izz="7.995957318055781e-07" ixy="-6.776263578034403e-21" iyz="0.0" ixz="1.463672932855431e-18" />
        </inertial>
        <visual name="right_caster_wheel_visual">
            <origin xyz="0.19659 -0.0140602 0.06830879000000001" rpy="-1.5707963267948966 -0.0 0.0" />
            <geometry>
                <mesh filename="meshes/right_caster_wheel.stl" scale="0.001 0.001 0.001" />
            </geometry>
            <material name="WHEEL_BLACK"/>
        </visual>
        <collision name="right_caster_wheel_collision">
            <origin xyz="0.19659 -0.0140602 0.06830879000000001" rpy="-1.5707963267948966 -0.0 0.0" />
            <geometry>
                <mesh filename="meshes/right_caster_wheel.stl" scale="0.001 0.001 0.001" />
            </geometry>
        </collision>
    </link>

    <link name="left_caster_connector">
        <inertial>
            <origin xyz="0.001405011953904811 2.1061910583277665e-05 -0.004221942265253933" rpy="0.0 -0.0 0.0" />
            <mass value="0.003960896655885583" />
            <inertia ixx="1.5703162104011186e-07" iyy="1.6777567965852564e-07" izz="1.744385929027209e-07" ixy="-5.709200946271459e-10" iyz="8.589987253464874e-10" ixz="4.192785338341846e-08" />
        </inertial>
        <visual name="left_caster_connector_visual">
            <origin xyz="0.20483935 0.06999121000000003 -0.0035800499999999948" rpy="0.0 -0.0 0.0" />
            <geometry>
                <mesh filename="meshes/left_caster_connector.stl" scale="0.001 0.001 0.001" />
            </geometry>
            <material name="CASTER_SILVER"/>
        </visual>
        <collision name="left_caster_connector_collision">
            <origin xyz="0.20483935 0.06999121000000003 -0.0035800499999999948" rpy="0.0 -0.0 0.0" />
            <geometry>
                <mesh filename="meshes/left_caster_connector.stl" scale="0.001 0.001 0.001" />
            </geometry>
        </collision>
    </link>

    <link name="left_caster_wheel">
        <inertial>
            <origin xyz="4.65898079227145e-09 -1.4002450621219965e-09 -0.0030121399559891503" rpy="0.0 -0.0 0.0" />
            <mass value="0.007044049388216182" />
            <inertia ixx="2.0613770434115268e-07" iyy="2.061377026189382e-07" izz="3.7586092361299424e-07" ixy="-3.38813178901459e-21" iyz="-3.1699860619156578e-21" ixz="-7.085104434733461e-19" />
        </inertial>
        <visual name="left_caster_wheel_visual">
            <origin xyz="0.195202854726494 -0.03091841522979793 0.06699120999999997" rpy="1.5707963267949003 -0.0 0.0" />
            <geometry>
                <mesh filename="meshes/left_caster_wheel.stl" scale="0.001 0.001 0.001" />
            </geometry>
            <material name="WHEEL_BLACK"/>
        </visual>
        <collision name="left_caster_wheel_collision">
            <origin xyz="0.195202854726494 -0.03091841522979793 0.06699120999999997" rpy="1.5707963267949003 -0.0 0.0" />
            <geometry>
                <mesh filename="meshes/left_caster_wheel.stl" scale="0.001 0.001 0.001" />
            </geometry>
        </collision>
    </link>

    <link name="right_wheel">
        <inertial>
            <origin xyz="-2.0393980372546137e-06 1.5439370204628489e-06 0.028132137687988515" rpy="0.0 -0.0 0.0" />
            <mass value="0.22391054430278606" />
            <inertia ixx="0.0002563570312582872" iyy="0.00025635053466559546" izz="0.00040423614978193575" ixy="-8.239692202193297e-10" iyz="-8.916929031960175e-09" ixz="1.1760889383465728e-08" />
        </inertial>
        <visual name="right_wheel_visual">
            <origin xyz="-0.03480209 0.055330050000000006 -0.13473818" rpy="1.5707963267948966 -0.0 0.0" />
            <geometry>
                <mesh filename="meshes/right_wheel.stl" scale="0.001 0.001 0.001" />
            </geometry>
            <material name="WHEEL_BLACK"/>
        </visual>
        <collision name="right_wheel_collision">
            <origin xyz="-0.03480209 0.055330050000000006 -0.13473818" rpy="1.5707963267948966 -0.0 0.0" />
            <geometry>
                <mesh filename="meshes/right_wheel.stl" scale="0.001 0.001 0.001" />
            </geometry>
        </collision>
    </link>

    <joint name="left_wheel_Revolute" type="continuous">
        <origin xyz="0.03480209 -0.13487021000000002 0.055330050000000006" rpy="1.5707963267948966 -0.0 0.0" />
        <parent link="base_link" />
        <child link="left_wheel" />
        <axis xyz="0.0 0.0 1.0" />
    </joint>
    <joint name="right_wheel_Revolute" type="continuous">
        <origin xyz="0.03480209 0.13473818 0.055330050000000006" rpy="-1.5707963267948966 -0.0 0.0" />
        <parent link="base_link" />
        <child link="right_wheel" />
        <axis xyz="0.0 0.0 1.0" />
    </joint>
    <joint name="top_lidar_Rigid" type="fixed">
        <origin xyz="-0.24983935 8.79e-06 0.14008005" rpy="0.0 -0.0 0.0" />
        <parent link="base_link" />
        <child link="top_lidar_sensor" />
    </joint>
    <joint name="bight_caster_Revolute" type="continuous">
        <origin xyz="-0.20483935 0.06500879000000001 0.02858005" rpy="0.0 -0.0 0.0" />
        <parent link="base_link" />
        <child link="right_caster_connector" />
        <axis xyz="0.0 0.0 1.0" />
    </joint>
    <joint name="right_caster_wheel_Revolute" type="continuous">
        <origin xyz="0.008249349999999999 0.003300000000000001 -0.014519849999999999" rpy="1.5707963267948966 -0.0 0.0" />
        <parent link="right_caster_connector" />
        <child link="right_caster_wheel" />
        <axis xyz="0.0 0.0 1.0" />
    </joint>
    <joint name="left_caster_Revolute" type="continuous">
        <origin xyz="-0.20483935 -0.06999121 0.02858005" rpy="0.0 -0.0 0.0" />
        <parent link="base_link" />
        <child link="left_caster_connector" />
        <axis xyz="0.0 0.0 1.0" />
    </joint>
    <joint name="left_caster_wheel_Revolute" type="continuous">
        <origin xyz="0.008249349999999999 0.003300000000000001 -0.014519849999999999" rpy="-1.5707963267949003 -0.0 0.0" />
        <parent link="left_caster_connector" />
        <child link="left_caster_wheel" />
        <axis xyz="0.0 -3.705369344686452e-15 1.0" />
    </joint>
</robot>